2023-05-29 22:56:09 INFO:     Will watch for changes in these directories: ['/']
2023-05-29 22:56:09 INFO:     Uvicorn running on http://0.0.0.0:8083 (Press CTRL+C to quit)
2023-05-29 22:56:09 INFO:     Started reloader process [1] using WatchFiles
2023-05-29 22:56:09 INFO:     Started server process [8]
2023-05-29 22:56:09 INFO:     Waiting for application startup.
2023-05-29 22:56:09 INFO:     Application startup complete.
2023-05-29 22:56:10 WARNING:root:Circuit "CB for Author service" is "CLOSED", failures: 0
2023-05-29 22:56:10 WARNING:root:
2023-05-29 22:56:11 WARNING:root:Circuit "CB for Author service" is "CLOSED", failures: 0
2023-05-29 22:56:11 WARNING:root:
2023-05-29 22:56:12 WARNING:root:Circuit "CB for Author service" is "CLOSED", failures: 0
2023-05-29 22:56:12 WARNING:root:
2023-05-29 22:56:13 WARNING:root:Circuit "CB for Author service" is "CLOSED", failures: 0
2023-05-29 22:56:13 WARNING:root:
2023-05-29 22:56:14 WARNING:root:Circuit "CB for Author service" is "CLOSED", failures: 0
2023-05-29 22:56:14 WARNING:root:
2023-05-29 22:56:15 INFO:root:Request successful
2023-05-29 22:56:15 WARNING:root:Circuit "CB for Author service" is "CLOSED", failures: 0
2023-05-29 22:56:15 WARNING:root:
2023-05-29 22:56:16 WARNING:root:Circuit "CB for Author service" is "CLOSED", failures: 0
2023-05-29 22:56:16 WARNING:root:
2023-05-29 22:56:17 INFO:root:Request successful
2023-05-29 22:56:18 WARNING:root:Circuit "CB for Author service" is "CLOSED", failures: 0
2023-05-29 22:56:18 WARNING:root:
2023-05-29 22:56:19 INFO:root:Request successful
2023-05-29 22:56:19 WARNING:root:Circuit "CB for Author service" is "CLOSED", failures: 0
2023-05-29 22:56:19 WARNING:root:
2023-05-29 22:56:20 WARNING:root:Circuit "CB for Author service" is "CLOSED", failures: 0
2023-05-29 22:56:20 WARNING:root:
2023-05-29 22:56:21 WARNING:root:Circuit "CB for Author service" is "CLOSED", failures: 0
2023-05-29 22:56:21 WARNING:root:
2023-05-29 22:56:22 WARNING:root:Circuit "CB for Author service" is "CLOSED", failures: 0
2023-05-29 22:56:22 WARNING:root:
2023-05-29 22:56:23 WARNING:root:Circuit "CB for Author service" is "CLOSED", failures: 0
2023-05-29 22:56:23 WARNING:root:
2023-05-29 22:56:24 WARNING:root:Circuit "CB for Author service" is "CLOSED", failures: 0
2023-05-29 22:56:24 WARNING:root:
2023-05-29 22:56:25 WARNING:root:Circuit "CB for Author service" is "CLOSED", failures: 0
2023-05-29 22:56:25 WARNING:root:
2023-05-29 22:56:25 INFO:root:Request successful
2023-05-29 22:56:26 WARNING:root:Circuit "CB for Author service" is "CLOSED", failures: 0
2023-05-29 22:56:26 WARNING:root:
2023-05-29 22:56:26 INFO:root:Request successful
2023-05-29 22:56:27 WARNING:root:Circuit "CB for Author service" is "CLOSED", failures: 0
2023-05-29 22:56:27 WARNING:root:
2023-05-29 22:56:27 INFO:root:Request successful
2023-05-29 22:56:28 WARNING:root:Circuit "CB for Author service" is "CLOSED", failures: 0
2023-05-29 22:56:28 WARNING:root:
2023-05-29 22:56:29 INFO:root:Request successful
2023-05-29 22:56:29 WARNING:root:Circuit "CB for Author service" is "CLOSED", failures: 0
2023-05-29 22:56:29 WARNING:root:
2023-05-29 22:56:30 INFO:root:Request successful
2023-05-29 22:56:15 Moore
2023-05-29 22:56:15 INFO:     172.20.0.1:47984 - "GET /presentationsAndAuthor/First%20Presentation HTTP/1.1" 200 OK
2023-05-29 22:56:17 Moore
2023-05-29 22:56:17 INFO:     172.20.0.1:47990 - "GET /presentationsAndAuthor/First%20Presentation HTTP/1.1" 200 OK
2023-05-29 22:56:19 Moore
2023-05-29 22:56:19 INFO:     172.20.0.1:47996 - "GET /presentationsAndAuthor/First%20Presentation HTTP/1.1" 200 OK
2023-05-29 22:56:25 Moore
2023-05-29 22:56:25 INFO:     172.20.0.1:48002 - "GET /presentationsAndAuthor/First%20Presentation HTTP/1.1" 200 OK
2023-05-29 22:56:26 Moore
2023-05-29 22:56:26 INFO:     172.20.0.1:48008 - "GET /presentationsAndAuthor/First%20Presentation HTTP/1.1" 200 OK
2023-05-29 22:56:27 Moore
2023-05-29 22:56:27 INFO:     172.20.0.1:48014 - "GET /presentationsAndAuthor/First%20Presentation HTTP/1.1" 200 OK
2023-05-29 22:56:29 Moore
2023-05-29 22:56:29 INFO:     172.20.0.1:48020 - "GET /presentationsAndAuthor/First%20Presentation HTTP/1.1" 200 OK
2023-05-29 22:56:30 Moore
2023-05-29 22:56:30 INFO:     172.20.0.1:48026 - "GET /presentationsAndAuthor/First%20Presentation HTTP/1.1" 200 OK
2023-05-29 22:56:31 Moore
2023-05-29 22:56:31 INFO:     172.20.0.1:48032 - "GET /presentationsAndAuthor/First%20Presentation HTTP/1.1" 200 OK
2023-05-29 22:56:32 Moore
2023-05-29 22:56:32 INFO:     172.20.0.1:48038 - "GET /presentationsAndAuthor/First%20Presentation HTTP/1.1" 200 OK
2023-05-29 22:56:30 WARNING:root:Circuit "CB for Author service" is "CLOSED", failures: 0
2023-05-29 22:56:30 WARNING:root:
2023-05-29 22:56:31 WARNING:root:Circuit "CB for Author service" is "CLOSED", failures: 0
2023-05-29 22:56:31 WARNING:root:
2023-05-29 22:56:31 INFO:root:Request successful
2023-05-29 22:56:32 WARNING:root:Circuit "CB for Author service" is "CLOSED", failures: 0
2023-05-29 22:56:32 WARNING:root:
2023-05-29 22:56:32 INFO:root:Request successful
2023-05-29 22:56:33 WARNING:root:Circuit "CB for Author service" is "CLOSED", failures: 0
2023-05-29 22:56:33 WARNING:root:
2023-05-29 22:56:33 WARNING:root:Request failed
2023-05-29 22:56:33 WARNING:root:Retrying request (1/1)
2023-05-29 22:56:33 WARNING:root:Request failed
2023-05-29 22:56:33 --- Logging error ---
2023-05-29 22:56:33 Traceback (most recent call last):
2023-05-29 22:56:33   File "/usr/local/lib/python3.10/dist-packages/urllib3/connection.py", line 174, in _new_conn
2023-05-29 22:56:33     conn = connection.create_connection(
2023-05-29 22:56:33   File "/usr/local/lib/python3.10/dist-packages/urllib3/util/connection.py", line 95, in create_connection
2023-05-29 22:56:33     raise err
2023-05-29 22:56:33   File "/usr/local/lib/python3.10/dist-packages/urllib3/util/connection.py", line 85, in create_connection
2023-05-29 22:56:33     sock.connect(sa)
2023-05-29 22:56:33 ConnectionRefusedError: [Errno 111] Connection refused
2023-05-29 22:56:33 
2023-05-29 22:56:33 During handling of the above exception, another exception occurred:
2023-05-29 22:56:33 
2023-05-29 22:56:33 Traceback (most recent call last):
2023-05-29 22:56:33   File "/usr/local/lib/python3.10/dist-packages/urllib3/connectionpool.py", line 703, in urlopen
2023-05-29 22:56:33     httplib_response = self._make_request(
2023-05-29 22:56:33   File "/usr/local/lib/python3.10/dist-packages/urllib3/connectionpool.py", line 398, in _make_request
2023-05-29 22:56:33     conn.request(method, url, **httplib_request_kw)
2023-05-29 22:56:33   File "/usr/local/lib/python3.10/dist-packages/urllib3/connection.py", line 239, in request
2023-05-29 22:56:33     super(HTTPConnection, self).request(method, url, body=body, headers=headers)
2023-05-29 22:56:33   File "/usr/lib/python3.10/http/client.py", line 1282, in request
2023-05-29 22:56:33     self._send_request(method, url, body, headers, encode_chunked)
2023-05-29 22:56:33   File "/usr/lib/python3.10/http/client.py", line 1328, in _send_request
2023-05-29 22:56:33     self.endheaders(body, encode_chunked=encode_chunked)
2023-05-29 22:56:33   File "/usr/lib/python3.10/http/client.py", line 1277, in endheaders
2023-05-29 22:56:33     self._send_output(message_body, encode_chunked=encode_chunked)
2023-05-29 22:56:33   File "/usr/lib/python3.10/http/client.py", line 1037, in _send_output
2023-05-29 22:56:33     self.send(msg)
2023-05-29 22:56:33   File "/usr/lib/python3.10/http/client.py", line 975, in send
2023-05-29 22:56:33     self.connect()
2023-05-29 22:56:33   File "/usr/local/lib/python3.10/dist-packages/urllib3/connection.py", line 205, in connect
2023-05-29 22:56:33     conn = self._new_conn()
2023-05-29 22:56:33   File "/usr/local/lib/python3.10/dist-packages/urllib3/connection.py", line 186, in _new_conn
2023-05-29 22:56:33     raise NewConnectionError(
2023-05-29 22:56:33 urllib3.exceptions.NewConnectionError: <urllib3.connection.HTTPConnection object at 0x7fc948d5f670>: Failed to establish a new connection: [Errno 111] Connection refused
2023-05-29 22:56:33 
2023-05-29 22:56:33 During handling of the above exception, another exception occurred:
2023-05-29 22:56:33 
2023-05-29 22:56:33 Traceback (most recent call last):
2023-05-29 22:56:33   File "/usr/local/lib/python3.10/dist-packages/requests/adapters.py", line 489, in send
2023-05-29 22:56:33     resp = conn.urlopen(
2023-05-29 22:56:33   File "/usr/local/lib/python3.10/dist-packages/urllib3/connectionpool.py", line 787, in urlopen
2023-05-29 22:56:33     retries = retries.increment(
2023-05-29 22:56:33   File "/usr/local/lib/python3.10/dist-packages/urllib3/util/retry.py", line 592, in increment
2023-05-29 22:56:33     raise MaxRetryError(_pool, url, error or ResponseError(cause))
2023-05-29 22:56:33 urllib3.exceptions.MaxRetryError: HTTPConnectionPool(host='service_author', port=8081): Max retries exceeded with url: /authors/1 (Caused by NewConnectionError('<urllib3.connection.HTTPConnection object at 0x7fc948d5f670>: Failed to establish a new connection: [Errno 111] Connection refused'))
2023-05-29 22:56:33 
2023-05-29 22:56:33 During handling of the above exception, another exception occurred:
2023-05-29 22:56:33 
2023-05-29 22:56:33 Traceback (most recent call last):
2023-05-29 22:56:33   File "/./custom_cb.py", line 29, in execute
2023-05-29 22:56:33     response = requests.get(url, timeout=3)
2023-05-29 22:56:33   File "/usr/local/lib/python3.10/dist-packages/requests/api.py", line 73, in get
2023-05-29 22:56:33     return request("get", url, params=params, **kwargs)
2023-05-29 22:56:33   File "/usr/local/lib/python3.10/dist-packages/requests/api.py", line 59, in request
2023-05-29 22:56:33     return session.request(method=method, url=url, **kwargs)
2023-05-29 22:56:33   File "/usr/local/lib/python3.10/dist-packages/requests/sessions.py", line 587, in request
2023-05-29 22:56:33     resp = self.send(prep, **send_kwargs)
2023-05-29 22:56:33   File "/usr/local/lib/python3.10/dist-packages/requests/sessions.py", line 701, in send
2023-05-29 22:56:33     r = adapter.send(request, **kwargs)
2023-05-29 22:56:33   File "/usr/local/lib/python3.10/dist-packages/requests/adapters.py", line 565, in send
2023-05-29 22:56:33     raise ConnectionError(e, request=request)
2023-05-29 22:56:33 requests.exceptions.ConnectionError: HTTPConnectionPool(host='service_author', port=8081): Max retries exceeded with url: /authors/1 (Caused by NewConnectionError('<urllib3.connection.HTTPConnection object at 0x7fc948d5f670>: Failed to establish a new connection: [Errno 111] Connection refused'))
2023-05-29 22:56:33 
2023-05-29 22:56:33 During handling of the above exception, another exception occurred:
2023-05-29 22:56:33 
2023-05-29 22:56:33 Traceback (most recent call last):
2023-05-29 22:56:33   File "/./service_main.py", line 69, in get_author
2023-05-29 22:56:33     response_author = cb.execute("http://" + service_author + "/authors/" + str(id), get_author_fallback())
2023-05-29 22:56:33   File "/./custom_cb.py", line 43, in execute
2023-05-29 22:56:33     raise ConnectionError('Service is unavailable')
2023-05-29 22:56:33 ConnectionError: Service is unavailable
2023-05-29 22:56:33 
2023-05-29 22:56:33 During handling of the above exception, another exception occurred:
2023-05-29 22:56:33 
2023-05-29 22:56:33 Traceback (most recent call last):
2023-05-29 22:56:33   File "/usr/lib/python3.10/logging/__init__.py", line 1100, in emit
2023-05-29 22:56:33     msg = self.format(record)
2023-05-29 22:56:33   File "/usr/lib/python3.10/logging/__init__.py", line 943, in format
2023-05-29 22:56:33     return fmt.format(record)
2023-05-29 22:56:33   File "/usr/lib/python3.10/logging/__init__.py", line 678, in format
2023-05-29 22:56:33     record.message = record.getMessage()
2023-05-29 22:56:33   File "/usr/lib/python3.10/logging/__init__.py", line 368, in getMessage
2023-05-29 22:56:33     msg = msg % self.args
2023-05-29 22:56:33 TypeError: not all arguments converted during string formatting
2023-05-29 22:56:33 Call stack:
2023-05-29 22:56:33   File "<string>", line 1, in <module>
2023-05-29 22:56:33   File "/usr/lib/python3.10/multiprocessing/spawn.py", line 116, in spawn_main
2023-05-29 22:56:33     exitcode = _main(fd, parent_sentinel)
2023-05-29 22:56:33   File "/usr/lib/python3.10/multiprocessing/spawn.py", line 129, in _main
2023-05-29 22:56:33     return self._bootstrap(parent_sentinel)
2023-05-29 22:56:33   File "/usr/lib/python3.10/multiprocessing/process.py", line 314, in _bootstrap
2023-05-29 22:56:33     self.run()
2023-05-29 22:56:33   File "/usr/lib/python3.10/multiprocessing/process.py", line 108, in run
2023-05-29 22:56:33     self._target(*self._args, **self._kwargs)
2023-05-29 22:56:33   File "/usr/local/lib/python3.10/dist-packages/uvicorn/_subprocess.py", line 76, in subprocess_started
2023-05-29 22:56:33     target(sockets=sockets)
2023-05-29 22:56:33   File "/usr/local/lib/python3.10/dist-packages/uvicorn/server.py", line 60, in run
2023-05-29 22:56:33     return asyncio.run(self.serve(sockets=sockets))
2023-05-29 22:56:33   File "/usr/lib/python3.10/asyncio/runners.py", line 44, in run
2023-05-29 22:56:33     return loop.run_until_complete(main)
2023-05-29 22:56:33   File "/usr/lib/python3.10/asyncio/base_events.py", line 633, in run_until_complete
2023-05-29 22:56:33     self.run_forever()
2023-05-29 22:56:33   File "/usr/lib/python3.10/asyncio/base_events.py", line 600, in run_forever
2023-05-29 22:56:33     self._run_once()
2023-05-29 22:56:33   File "/usr/lib/python3.10/asyncio/base_events.py", line 1896, in _run_once
2023-05-29 22:56:33     handle._run()
2023-05-29 22:56:33   File "/usr/lib/python3.10/asyncio/events.py", line 80, in _run
2023-05-29 22:56:33     self._context.run(self._callback, *self._args)
2023-05-29 22:56:33   File "/usr/local/lib/python3.10/dist-packages/uvicorn/protocols/http/httptools_impl.py", line 419, in run_asgi
2023-05-29 22:56:33     result = await app(  # type: ignore[func-returns-value]
2023-05-29 22:56:33   File "/usr/local/lib/python3.10/dist-packages/uvicorn/middleware/proxy_headers.py", line 78, in __call__
2023-05-29 22:56:33     return await self.app(scope, receive, send)
2023-05-29 22:56:33   File "/usr/local/lib/python3.10/dist-packages/fastapi/applications.py", line 271, in __call__
2023-05-29 22:56:33     await super().__call__(scope, receive, send)
2023-05-29 22:56:33   File "/usr/local/lib/python3.10/dist-packages/starlette/applications.py", line 118, in __call__
2023-05-29 22:56:33     await self.middleware_stack(scope, receive, send)
2023-05-29 22:56:33   File "/usr/local/lib/python3.10/dist-packages/starlette/middleware/errors.py", line 162, in __call__
2023-05-29 22:56:33     await self.app(scope, receive, _send)
2023-05-29 22:56:33   File "/usr/local/lib/python3.10/dist-packages/starlette/middleware/exceptions.py", line 68, in __call__
2023-05-29 22:56:33     await self.app(scope, receive, sender)
2023-05-29 22:56:33   File "/usr/local/lib/python3.10/dist-packages/fastapi/middleware/asyncexitstack.py", line 18, in __call__
2023-05-29 22:56:33     await self.app(scope, receive, send)
2023-05-29 22:56:33   File "/usr/local/lib/python3.10/dist-packages/starlette/routing.py", line 706, in __call__
2023-05-29 22:56:33     await route.handle(scope, receive, send)
2023-05-29 22:56:33   File "/usr/local/lib/python3.10/dist-packages/starlette/routing.py", line 276, in handle
2023-05-29 22:56:33     await self.app(scope, receive, send)
2023-05-29 22:56:33   File "/usr/local/lib/python3.10/dist-packages/starlette/routing.py", line 66, in app
2023-05-29 22:56:33     response = await func(request)
2023-05-29 22:56:33   File "/usr/local/lib/python3.10/dist-packages/fastapi/routing.py", line 237, in app
2023-05-29 22:56:33     raw_response = await run_endpoint_function(
2023-05-29 22:56:33   File "/usr/local/lib/python3.10/dist-packages/fastapi/routing.py", line 163, in run_endpoint_function
2023-05-29 22:56:33     return await dependant.call(**values)
2023-05-29 22:56:33   File "/./service_main.py", line 103, in read_presentation
2023-05-29 22:56:33     author = get_author(presentation.author_id)
2023-05-29 22:56:33 INFO:     172.20.0.1:48044 - "GET /presentationsAndAuthor/First%20Presentation HTTP/1.1" 500 Internal Server Error
2023-05-29 22:56:33   File "/./service_main.py", line 71, in get_author
2023-05-29 22:56:33     logging.warning(">>> Error Connecting:", errc)
2023-05-29 22:56:33 Message: '>>> Error Connecting:'
2023-05-29 22:56:33 Arguments: (ConnectionError('Service is unavailable'),)
2023-05-29 22:56:34 WARNING:root:Circuit "CB for Author service" is "CLOSED", failures: 2
2023-05-29 22:56:34 WARNING:root:
2023-05-29 22:56:35 WARNING:root:Circuit "CB for Author service" is "CLOSED", failures: 2
2023-05-29 22:56:35 WARNING:root:
2023-05-29 22:56:36 WARNING:root:Circuit "CB for Author service" is "CLOSED", failures: 2
2023-05-29 22:56:36 WARNING:root:
2023-05-29 22:56:37 WARNING:root:Circuit "CB for Author service" is "CLOSED", failures: 2
2023-05-29 22:56:37 WARNING:root:
2023-05-29 22:56:38 WARNING:root:Circuit "CB for Author service" is "CLOSED", failures: 2
2023-05-29 22:56:38 WARNING:root:
2023-05-29 22:56:39 WARNING:root:Circuit "CB for Author service" is "CLOSED", failures: 2
2023-05-29 22:56:39 WARNING:root:
2023-05-29 22:56:40 WARNING:root:Circuit "CB for Author service" is "CLOSED", failures: 2
2023-05-29 22:56:40 WARNING:root:
2023-05-29 22:56:41 WARNING:root:Circuit "CB for Author service" is "CLOSED", failures: 2
2023-05-29 22:56:41 WARNING:root:
2023-05-29 22:56:42 WARNING:root:Circuit "CB for Author service" is "CLOSED", failures: 2
2023-05-29 22:56:42 WARNING:root:
2023-05-29 22:56:43 WARNING:root:Circuit "CB for Author service" is "CLOSED", failures: 2
2023-05-29 22:56:43 WARNING:root:
2023-05-29 22:56:44 WARNING:root:Circuit "CB for Author service" is "CLOSED", failures: 2
2023-05-29 22:56:44 WARNING:root:
2023-05-29 22:56:45 WARNING:root:Circuit "CB for Author service" is "CLOSED", failures: 2
2023-05-29 22:56:45 WARNING:root:
2023-05-29 22:56:45 WARNING:root:Request failed
2023-05-29 22:56:45 --- Logging error ---
2023-05-29 22:56:45 Traceback (most recent call last):
2023-05-29 22:56:45   File "/usr/local/lib/python3.10/dist-packages/urllib3/connection.py", line 174, in _new_conn
2023-05-29 22:56:45     conn = connection.create_connection(
2023-05-29 22:56:45   File "/usr/local/lib/python3.10/dist-packages/urllib3/util/connection.py", line 72, in create_connection
2023-05-29 22:56:45     for res in socket.getaddrinfo(host, port, family, socket.SOCK_STREAM):
2023-05-29 22:56:45   File "/usr/lib/python3.10/socket.py", line 955, in getaddrinfo
2023-05-29 22:56:45     for res in _socket.getaddrinfo(host, port, family, type, proto, flags):
2023-05-29 22:56:45 socket.gaierror: [Errno -3] Temporary failure in name resolution
2023-05-29 22:56:45 
2023-05-29 22:56:45 During handling of the above exception, another exception occurred:
2023-05-29 22:56:45 
2023-05-29 22:56:45 Traceback (most recent call last):
2023-05-29 22:56:45   File "/usr/local/lib/python3.10/dist-packages/urllib3/connectionpool.py", line 703, in urlopen
2023-05-29 22:56:45     httplib_response = self._make_request(
2023-05-29 22:56:45   File "/usr/local/lib/python3.10/dist-packages/urllib3/connectionpool.py", line 398, in _make_request
2023-05-29 22:56:45     conn.request(method, url, **httplib_request_kw)
2023-05-29 22:56:45   File "/usr/local/lib/python3.10/dist-packages/urllib3/connection.py", line 239, in request
2023-05-29 22:56:45     super(HTTPConnection, self).request(method, url, body=body, headers=headers)
2023-05-29 22:56:45   File "/usr/lib/python3.10/http/client.py", line 1282, in request
2023-05-29 22:56:45     self._send_request(method, url, body, headers, encode_chunked)
2023-05-29 22:56:45   File "/usr/lib/python3.10/http/client.py", line 1328, in _send_request
2023-05-29 22:56:45     self.endheaders(body, encode_chunked=encode_chunked)
2023-05-29 22:56:45   File "/usr/lib/python3.10/http/client.py", line 1277, in endheaders
2023-05-29 22:56:45     self._send_output(message_body, encode_chunked=encode_chunked)
2023-05-29 22:56:45   File "/usr/lib/python3.10/http/client.py", line 1037, in _send_output
2023-05-29 22:56:45     self.send(msg)
2023-05-29 22:56:45   File "/usr/lib/python3.10/http/client.py", line 975, in send
2023-05-29 22:56:45     self.connect()
2023-05-29 22:56:45   File "/usr/local/lib/python3.10/dist-packages/urllib3/connection.py", line 205, in connect
2023-05-29 22:56:45     conn = self._new_conn()
2023-05-29 22:56:45   File "/usr/local/lib/python3.10/dist-packages/urllib3/connection.py", line 186, in _new_conn
2023-05-29 22:56:45     raise NewConnectionError(
2023-05-29 22:56:45 urllib3.exceptions.NewConnectionError: <urllib3.connection.HTTPConnection object at 0x7fc948d5e950>: Failed to establish a new connection: [Errno -3] Temporary failure in name resolution
2023-05-29 22:56:45 
2023-05-29 22:56:45 During handling of the above exception, another exception occurred:
2023-05-29 22:56:45 
2023-05-29 22:56:45 Traceback (most recent call last):
2023-05-29 22:56:45   File "/usr/local/lib/python3.10/dist-packages/requests/adapters.py", line 489, in send
2023-05-29 22:56:45     resp = conn.urlopen(
2023-05-29 22:56:45   File "/usr/local/lib/python3.10/dist-packages/urllib3/connectionpool.py", line 787, in urlopen
2023-05-29 22:56:45     retries = retries.increment(
2023-05-29 22:56:45   File "/usr/local/lib/python3.10/dist-packages/urllib3/util/retry.py", line 592, in increment
2023-05-29 22:56:45     raise MaxRetryError(_pool, url, error or ResponseError(cause))
2023-05-29 22:56:45 urllib3.exceptions.MaxRetryError: HTTPConnectionPool(host='service_author', port=8081): Max retries exceeded with url: /authors/1 (Caused by NewConnectionError('<urllib3.connection.HTTPConnection object at 0x7fc948d5e950>: Failed to establish a new connection: [Errno -3] Temporary failure in name resolution'))
2023-05-29 22:56:45 
2023-05-29 22:56:45 During handling of the above exception, another exception occurred:
2023-05-29 22:56:45 
2023-05-29 22:56:45 Traceback (most recent call last):
2023-05-29 22:56:45   File "/./custom_cb.py", line 29, in execute
2023-05-29 22:56:45     response = requests.get(url, timeout=3)
2023-05-29 22:56:45   File "/usr/local/lib/python3.10/dist-packages/requests/api.py", line 73, in get
2023-05-29 22:56:45     return request("get", url, params=params, **kwargs)
2023-05-29 22:56:45   File "/usr/local/lib/python3.10/dist-packages/requests/api.py", line 59, in request
2023-05-29 22:56:45 INFO:     172.20.0.1:48052 - "GET /presentationsAndAuthor/First%20Presentation HTTP/1.1" 500 Internal Server Error
2023-05-29 22:56:48 temporary unavailable
2023-05-29 22:56:48 INFO:     172.20.0.1:48056 - "GET /presentationsAndAuthor/First%20Presentation HTTP/1.1" 200 OK
2023-05-29 22:56:50 temporary unavailable
2023-05-29 22:56:50 INFO:     172.20.0.1:48060 - "GET /presentationsAndAuthor/First%20Presentation HTTP/1.1" 200 OK
2023-05-29 22:56:51 temporary unavailable
2023-05-29 22:56:51 INFO:     172.20.0.1:48064 - "GET /presentationsAndAuthor/First%20Presentation HTTP/1.1" 200 OK
2023-05-29 22:56:52 temporary unavailable
2023-05-29 22:56:52 INFO:     172.20.0.1:48068 - "GET /presentationsAndAuthor/First%20Presentation HTTP/1.1" 200 OK
2023-05-29 22:56:53 temporary unavailable
2023-05-29 22:56:53 INFO:     172.20.0.1:48072 - "GET /presentationsAndAuthor/First%20Presentation HTTP/1.1" 200 OK
2023-05-29 22:56:54 temporary unavailable
2023-05-29 22:56:54 INFO:     172.20.0.1:48076 - "GET /presentationsAndAuthor/First%20Presentation HTTP/1.1" 200 OK
2023-05-29 22:56:55 temporary unavailable
2023-05-29 22:56:55 INFO:     172.20.0.1:48080 - "GET /presentationsAndAuthor/First%20Presentation HTTP/1.1" 200 OK
2023-05-29 22:57:05 INFO:     172.20.0.1:48084 - "GET /presentationsAndAuthor/First%20Presentation HTTP/1.1" 500 Internal Server Error
2023-05-29 22:57:06 temporary unavailable
2023-05-29 22:57:06 INFO:     172.20.0.1:48088 - "GET /presentationsAndAuthor/First%20Presentation HTTP/1.1" 200 OK
2023-05-29 22:57:06 temporary unavailable
2023-05-29 22:57:06 INFO:     172.20.0.1:48092 - "GET /presentationsAndAuthor/First%20Presentation HTTP/1.1" 200 OK
2023-05-29 22:57:06 temporary unavailable
2023-05-29 22:57:06 INFO:     172.20.0.1:48096 - "GET /presentationsAndAuthor/First%20Presentation HTTP/1.1" 200 OK
2023-05-29 22:57:07 temporary unavailable
2023-05-29 22:57:07 INFO:     172.20.0.1:48100 - "GET /presentationsAndAuthor/First%20Presentation HTTP/1.1" 200 OK
2023-05-29 22:57:08 temporary unavailable
2023-05-29 22:57:08 INFO:     172.20.0.1:48104 - "GET /presentationsAndAuthor/First%20Presentation HTTP/1.1" 200 OK
2023-05-29 22:57:09 temporary unavailable
2023-05-29 22:57:09 INFO:     172.20.0.1:48108 - "GET /presentationsAndAuthor/First%20Presentation HTTP/1.1" 200 OK
2023-05-29 22:57:10 temporary unavailable
2023-05-29 22:57:10 INFO:     172.20.0.1:48112 - "GET /presentationsAndAuthor/First%20Presentation HTTP/1.1" 200 OK
2023-05-29 22:56:45     return session.request(method=method, url=url, **kwargs)
2023-05-29 22:56:45   File "/usr/local/lib/python3.10/dist-packages/requests/sessions.py", line 587, in request
2023-05-29 22:56:45     resp = self.send(prep, **send_kwargs)
2023-05-29 22:56:45   File "/usr/local/lib/python3.10/dist-packages/requests/sessions.py", line 701, in send
2023-05-29 22:56:45     r = adapter.send(request, **kwargs)
2023-05-29 22:56:45   File "/usr/local/lib/python3.10/dist-packages/requests/adapters.py", line 565, in send
2023-05-29 22:56:45     raise ConnectionError(e, request=request)
2023-05-29 22:56:45 requests.exceptions.ConnectionError: HTTPConnectionPool(host='service_author', port=8081): Max retries exceeded with url: /authors/1 (Caused by NewConnectionError('<urllib3.connection.HTTPConnection object at 0x7fc948d5e950>: Failed to establish a new connection: [Errno -3] Temporary failure in name resolution'))
2023-05-29 22:56:45 
2023-05-29 22:56:45 During handling of the above exception, another exception occurred:
2023-05-29 22:56:45 
2023-05-29 22:56:45 Traceback (most recent call last):
2023-05-29 22:56:45   File "/./service_main.py", line 69, in get_author
2023-05-29 22:56:45     response_author = cb.execute("http://" + service_author + "/authors/" + str(id), get_author_fallback())
2023-05-29 22:56:45   File "/./custom_cb.py", line 41, in execute
2023-05-29 22:56:45     raise ConnectionError('Service is unavailable')
2023-05-29 22:56:45 ConnectionError: Service is unavailable
2023-05-29 22:56:45 
2023-05-29 22:56:45 During handling of the above exception, another exception occurred:
2023-05-29 22:56:45 
2023-05-29 22:56:45 Traceback (most recent call last):
2023-05-29 22:56:45   File "/usr/lib/python3.10/logging/__init__.py", line 1100, in emit
2023-05-29 22:56:45     msg = self.format(record)
2023-05-29 22:56:45   File "/usr/lib/python3.10/logging/__init__.py", line 943, in format
2023-05-29 22:56:45     return fmt.format(record)
2023-05-29 22:56:45   File "/usr/lib/python3.10/logging/__init__.py", line 678, in format
2023-05-29 22:56:45     record.message = record.getMessage()
2023-05-29 22:56:45   File "/usr/lib/python3.10/logging/__init__.py", line 368, in getMessage
2023-05-29 22:56:45     msg = msg % self.args
2023-05-29 22:56:45 TypeError: not all arguments converted during string formatting
2023-05-29 22:56:45 Call stack:
2023-05-29 22:56:45   File "<string>", line 1, in <module>
2023-05-29 22:56:45   File "/usr/lib/python3.10/multiprocessing/spawn.py", line 116, in spawn_main
2023-05-29 22:56:45     exitcode = _main(fd, parent_sentinel)
2023-05-29 22:56:45   File "/usr/lib/python3.10/multiprocessing/spawn.py", line 129, in _main
2023-05-29 22:56:45     return self._bootstrap(parent_sentinel)
2023-05-29 22:56:45   File "/usr/lib/python3.10/multiprocessing/process.py", line 314, in _bootstrap
2023-05-29 22:56:45     self.run()
2023-05-29 22:56:45   File "/usr/lib/python3.10/multiprocessing/process.py", line 108, in run
2023-05-29 22:56:45     self._target(*self._args, **self._kwargs)
2023-05-29 22:56:45   File "/usr/local/lib/python3.10/dist-packages/uvicorn/_subprocess.py", line 76, in subprocess_started
2023-05-29 22:56:45     target(sockets=sockets)
2023-05-29 22:56:45   File "/usr/local/lib/python3.10/dist-packages/uvicorn/server.py", line 60, in run
2023-05-29 22:56:45     return asyncio.run(self.serve(sockets=sockets))
2023-05-29 22:56:45   File "/usr/lib/python3.10/asyncio/runners.py", line 44, in run
2023-05-29 22:56:45     return loop.run_until_complete(main)
2023-05-29 22:56:45   File "/usr/lib/python3.10/asyncio/base_events.py", line 633, in run_until_complete
2023-05-29 22:56:45     self.run_forever()
2023-05-29 22:56:45   File "/usr/lib/python3.10/asyncio/base_events.py", line 600, in run_forever
2023-05-29 22:56:45     self._run_once()
2023-05-29 22:56:45   File "/usr/lib/python3.10/asyncio/base_events.py", line 1896, in _run_once
2023-05-29 22:56:45     handle._run()
2023-05-29 22:56:45   File "/usr/lib/python3.10/asyncio/events.py", line 80, in _run
2023-05-29 22:56:45     self._context.run(self._callback, *self._args)
2023-05-29 22:56:45   File "/usr/local/lib/python3.10/dist-packages/uvicorn/protocols/http/httptools_impl.py", line 419, in run_asgi
2023-05-29 22:56:45     result = await app(  # type: ignore[func-returns-value]
2023-05-29 22:56:45   File "/usr/local/lib/python3.10/dist-packages/uvicorn/middleware/proxy_headers.py", line 78, in __call__
2023-05-29 22:56:45     return await self.app(scope, receive, send)
2023-05-29 22:56:45   File "/usr/local/lib/python3.10/dist-packages/fastapi/applications.py", line 271, in __call__
2023-05-29 22:56:45     await super().__call__(scope, receive, send)
2023-05-29 22:56:45   File "/usr/local/lib/python3.10/dist-packages/starlette/applications.py", line 118, in __call__
2023-05-29 22:56:45     await self.middleware_stack(scope, receive, send)
2023-05-29 22:56:45   File "/usr/local/lib/python3.10/dist-packages/starlette/middleware/errors.py", line 162, in __call__
2023-05-29 22:56:45     await self.app(scope, receive, _send)
2023-05-29 22:56:45   File "/usr/local/lib/python3.10/dist-packages/starlette/middleware/exceptions.py", line 68, in __call__
2023-05-29 22:56:45     await self.app(scope, receive, sender)
2023-05-29 22:56:45   File "/usr/local/lib/python3.10/dist-packages/fastapi/middleware/asyncexitstack.py", line 18, in __call__
2023-05-29 22:56:45     await self.app(scope, receive, send)
2023-05-29 22:56:45   File "/usr/local/lib/python3.10/dist-packages/starlette/routing.py", line 706, in __call__
2023-05-29 22:56:45     await route.handle(scope, receive, send)
2023-05-29 22:56:45   File "/usr/local/lib/python3.10/dist-packages/starlette/routing.py", line 276, in handle
2023-05-29 22:56:45     await self.app(scope, receive, send)
2023-05-29 22:56:45   File "/usr/local/lib/python3.10/dist-packages/starlette/routing.py", line 66, in app
2023-05-29 22:56:45     response = await func(request)
2023-05-29 22:56:45   File "/usr/local/lib/python3.10/dist-packages/fastapi/routing.py", line 237, in app
2023-05-29 22:56:45     raw_response = await run_endpoint_function(
2023-05-29 22:56:45   File "/usr/local/lib/python3.10/dist-packages/fastapi/routing.py", line 163, in run_endpoint_function
2023-05-29 22:56:45     return await dependant.call(**values)
2023-05-29 22:56:45   File "/./service_main.py", line 103, in read_presentation
2023-05-29 22:56:45     author = get_author(presentation.author_id)
2023-05-29 22:56:45   File "/./service_main.py", line 71, in get_author
2023-05-29 22:56:45     logging.warning(">>> Error Connecting:", errc)
2023-05-29 22:56:45 Message: '>>> Error Connecting:'
2023-05-29 22:56:45 Arguments: (ConnectionError('Service is unavailable'),)
2023-05-29 22:56:46 WARNING:root:Circuit "CB for Author service" is "OPEN", failures: 3
2023-05-29 22:56:46 WARNING:root:
2023-05-29 22:56:47 WARNING:root:Circuit "CB for Author service" is "OPEN", failures: 3
2023-05-29 22:56:47 WARNING:root:
2023-05-29 22:56:48 INFO:root:Stay Circuit breaker open
2023-05-29 22:56:48 WARNING:root:Circuit "CB for Author service" is "OPEN", failures: 3
2023-05-29 22:56:48 WARNING:root:
2023-05-29 22:56:49 WARNING:root:Circuit "CB for Author service" is "OPEN", failures: 3
2023-05-29 22:56:49 WARNING:root:
2023-05-29 22:56:50 INFO:root:Stay Circuit breaker open
2023-05-29 22:56:50 WARNING:root:Circuit "CB for Author service" is "OPEN", failures: 3
2023-05-29 22:56:50 WARNING:root:
2023-05-29 22:56:51 WARNING:root:Circuit "CB for Author service" is "OPEN", failures: 3
2023-05-29 22:56:51 WARNING:root:
2023-05-29 22:56:51 INFO:root:Stay Circuit breaker open
2023-05-29 22:56:52 WARNING:root:Circuit "CB for Author service" is "OPEN", failures: 3
2023-05-29 22:56:52 WARNING:root:
2023-05-29 22:56:52 INFO:root:Stay Circuit breaker open
2023-05-29 22:56:53 INFO:root:Stay Circuit breaker open
2023-05-29 22:56:53 WARNING:root:Circuit "CB for Author service" is "OPEN", failures: 3
2023-05-29 22:56:53 WARNING:root:
2023-05-29 22:56:54 INFO:root:Stay Circuit breaker open
2023-05-29 22:56:54 WARNING:root:Circuit "CB for Author service" is "OPEN", failures: 3
2023-05-29 22:56:54 WARNING:root:
2023-05-29 22:56:55 INFO:root:Stay Circuit breaker open
2023-05-29 22:56:55 WARNING:root:Circuit "CB for Author service" is "OPEN", failures: 3
2023-05-29 22:56:55 WARNING:root:
2023-05-29 22:56:55 INFO:root:Try half_open Circuit breaker
2023-05-29 22:56:56 WARNING:root:Circuit "CB for Author service" is "HALF_OPEN", failures: 3
2023-05-29 22:56:56 WARNING:root:
2023-05-29 22:56:57 WARNING:root:Circuit "CB for Author service" is "HALF_OPEN", failures: 3
2023-05-29 22:56:57 WARNING:root:
2023-05-29 22:56:58 WARNING:root:Circuit "CB for Author service" is "HALF_OPEN", failures: 3
2023-05-29 22:56:58 WARNING:root:
2023-05-29 22:56:59 WARNING:root:Circuit "CB for Author service" is "HALF_OPEN", failures: 3
2023-05-29 22:56:59 WARNING:root:
2023-05-29 22:57:00 WARNING:root:Circuit "CB for Author service" is "HALF_OPEN", failures: 3
2023-05-29 22:57:00 WARNING:root:
2023-05-29 22:57:01 WARNING:root:Circuit "CB for Author service" is "HALF_OPEN", failures: 3
2023-05-29 22:57:01 WARNING:root:
2023-05-29 22:57:02 WARNING:root:Circuit "CB for Author service" is "HALF_OPEN", failures: 3
2023-05-29 22:57:02 WARNING:root:
2023-05-29 22:57:03 WARNING:root:Circuit "CB for Author service" is "HALF_OPEN", failures: 3
2023-05-29 22:57:03 WARNING:root:
2023-05-29 22:57:04 WARNING:root:Circuit "CB for Author service" is "HALF_OPEN", failures: 3
2023-05-29 22:57:04 WARNING:root:
2023-05-29 22:57:05 WARNING:root:Circuit "CB for Author service" is "HALF_OPEN", failures: 3
2023-05-29 22:57:05 WARNING:root:
2023-05-29 22:57:05 WARNING:root:Request failed
2023-05-29 22:57:05 --- Logging error ---
2023-05-29 22:57:05 Traceback (most recent call last):
2023-05-29 22:57:05   File "/usr/local/lib/python3.10/dist-packages/urllib3/connection.py", line 174, in _new_conn
2023-05-29 22:57:05     conn = connection.create_connection(
2023-05-29 22:57:05   File "/usr/local/lib/python3.10/dist-packages/urllib3/util/connection.py", line 72, in create_connection
2023-05-29 22:57:05     for res in socket.getaddrinfo(host, port, family, socket.SOCK_STREAM):
2023-05-29 22:57:05   File "/usr/lib/python3.10/socket.py", line 955, in getaddrinfo
2023-05-29 22:57:05     for res in _socket.getaddrinfo(host, port, family, type, proto, flags):
2023-05-29 22:57:05 socket.gaierror: [Errno -3] Temporary failure in name resolution
2023-05-29 22:57:05 
2023-05-29 22:57:05 During handling of the above exception, another exception occurred:
2023-05-29 22:57:05 
2023-05-29 22:57:05 Traceback (most recent call last):
2023-05-29 22:57:05   File "/usr/local/lib/python3.10/dist-packages/urllib3/connectionpool.py", line 703, in urlopen
2023-05-29 22:57:05     httplib_response = self._make_request(
2023-05-29 22:57:05   File "/usr/local/lib/python3.10/dist-packages/urllib3/connectionpool.py", line 398, in _make_request
2023-05-29 22:57:05     conn.request(method, url, **httplib_request_kw)
2023-05-29 22:57:05   File "/usr/local/lib/python3.10/dist-packages/urllib3/connection.py", line 239, in request
2023-05-29 22:57:05     super(HTTPConnection, self).request(method, url, body=body, headers=headers)
2023-05-29 22:57:05   File "/usr/lib/python3.10/http/client.py", line 1282, in request
2023-05-29 22:57:05     self._send_request(method, url, body, headers, encode_chunked)
2023-05-29 22:57:05   File "/usr/lib/python3.10/http/client.py", line 1328, in _send_request
2023-05-29 22:57:05     self.endheaders(body, encode_chunked=encode_chunked)
2023-05-29 22:57:05   File "/usr/lib/python3.10/http/client.py", line 1277, in endheaders
2023-05-29 22:57:05     self._send_output(message_body, encode_chunked=encode_chunked)
2023-05-29 22:57:05   File "/usr/lib/python3.10/http/client.py", line 1037, in _send_output
2023-05-29 22:57:05     self.send(msg)
2023-05-29 22:57:05   File "/usr/lib/python3.10/http/client.py", line 975, in send
2023-05-29 22:57:05     self.connect()
2023-05-29 22:57:05   File "/usr/local/lib/python3.10/dist-packages/urllib3/connection.py", line 205, in connect
2023-05-29 22:57:05     conn = self._new_conn()
2023-05-29 22:57:05   File "/usr/local/lib/python3.10/dist-packages/urllib3/connection.py", line 186, in _new_conn
2023-05-29 22:57:05     raise NewConnectionError(
2023-05-29 22:57:05 urllib3.exceptions.NewConnectionError: <urllib3.connection.HTTPConnection object at 0x7fc9482f8670>: Failed to establish a new connection: [Errno -3] Temporary failure in name resolution
2023-05-29 22:57:05 
2023-05-29 22:57:05 During handling of the above exception, another exception occurred:
2023-05-29 22:57:05 
2023-05-29 22:57:05 Traceback (most recent call last):
2023-05-29 22:57:05   File "/usr/local/lib/python3.10/dist-packages/requests/adapters.py", line 489, in send
2023-05-29 22:57:05     resp = conn.urlopen(
2023-05-29 22:57:05   File "/usr/local/lib/python3.10/dist-packages/urllib3/connectionpool.py", line 787, in urlopen
2023-05-29 22:57:05     retries = retries.increment(
2023-05-29 22:57:05   File "/usr/local/lib/python3.10/dist-packages/urllib3/util/retry.py", line 592, in increment
2023-05-29 22:57:05     raise MaxRetryError(_pool, url, error or ResponseError(cause))
2023-05-29 22:57:05 urllib3.exceptions.MaxRetryError: HTTPConnectionPool(host='service_author', port=8081): Max retries exceeded with url: /authors/1 (Caused by NewConnectionError('<urllib3.connection.HTTPConnection object at 0x7fc9482f8670>: Failed to establish a new connection: [Errno -3] Temporary failure in name resolution'))
2023-05-29 22:57:05 
2023-05-29 22:57:05 During handling of the above exception, another exception occurred:
2023-05-29 22:57:05 
2023-05-29 22:57:05 Traceback (most recent call last):
2023-05-29 22:57:05   File "/./custom_cb.py", line 29, in execute
2023-05-29 22:57:05     response = requests.get(url, timeout=3)
2023-05-29 22:57:05   File "/usr/local/lib/python3.10/dist-packages/requests/api.py", line 73, in get
2023-05-29 22:57:05     return request("get", url, params=params, **kwargs)
2023-05-29 22:57:05   File "/usr/local/lib/python3.10/dist-packages/requests/api.py", line 59, in request
2023-05-29 22:57:05     return session.request(method=method, url=url, **kwargs)
2023-05-29 22:57:05   File "/usr/local/lib/python3.10/dist-packages/requests/sessions.py", line 587, in request
2023-05-29 22:57:05     resp = self.send(prep, **send_kwargs)
2023-05-29 22:57:05   File "/usr/local/lib/python3.10/dist-packages/requests/sessions.py", line 701, in send
2023-05-29 22:57:05     r = adapter.send(request, **kwargs)
2023-05-29 22:57:05   File "/usr/local/lib/python3.10/dist-packages/requests/adapters.py", line 565, in send
2023-05-29 22:57:05     raise ConnectionError(e, request=request)
2023-05-29 22:57:05 requests.exceptions.ConnectionError: HTTPConnectionPool(host='service_author', port=8081): Max retries exceeded with url: /authors/1 (Caused by NewConnectionError('<urllib3.connection.HTTPConnection object at 0x7fc9482f8670>: Failed to establish a new connection: [Errno -3] Temporary failure in name resolution'))
2023-05-29 22:57:05 
2023-05-29 22:57:05 During handling of the above exception, another exception occurred:
2023-05-29 22:57:05 
2023-05-29 22:57:05 Traceback (most recent call last):
2023-05-29 22:57:05   File "/./service_main.py", line 69, in get_author
2023-05-29 22:57:05     response_author = cb.execute("http://" + service_author + "/authors/" + str(id), get_author_fallback())
2023-05-29 22:57:05   File "/./custom_cb.py", line 41, in execute
2023-05-29 22:57:05     raise ConnectionError('Service is unavailable')
2023-05-29 22:57:05 ConnectionError: Service is unavailable
2023-05-29 22:57:05 
2023-05-29 22:57:05 During handling of the above exception, another exception occurred:
2023-05-29 22:57:05 
2023-05-29 22:57:05 Traceback (most recent call last):
2023-05-29 22:57:05   File "/usr/lib/python3.10/logging/__init__.py", line 1100, in emit
2023-05-29 22:57:05     msg = self.format(record)
2023-05-29 22:57:05   File "/usr/lib/python3.10/logging/__init__.py", line 943, in format
2023-05-29 22:57:05     return fmt.format(record)
2023-05-29 22:57:05   File "/usr/lib/python3.10/logging/__init__.py", line 678, in format
2023-05-29 22:57:05     record.message = record.getMessage()
2023-05-29 22:57:05   File "/usr/lib/python3.10/logging/__init__.py", line 368, in getMessage
2023-05-29 22:57:05     msg = msg % self.args
2023-05-29 22:57:05 TypeError: not all arguments converted during string formatting
2023-05-29 22:57:05 Call stack:
2023-05-29 22:57:05   File "<string>", line 1, in <module>
2023-05-29 22:57:05   File "/usr/lib/python3.10/multiprocessing/spawn.py", line 116, in spawn_main
2023-05-29 22:57:05     exitcode = _main(fd, parent_sentinel)
2023-05-29 22:57:05   File "/usr/lib/python3.10/multiprocessing/spawn.py", line 129, in _main
2023-05-29 22:57:05     return self._bootstrap(parent_sentinel)
2023-05-29 22:57:05   File "/usr/lib/python3.10/multiprocessing/process.py", line 314, in _bootstrap
2023-05-29 22:57:05     self.run()
2023-05-29 22:57:05   File "/usr/lib/python3.10/multiprocessing/process.py", line 108, in run
2023-05-29 22:57:05     self._target(*self._args, **self._kwargs)
2023-05-29 22:57:05   File "/usr/local/lib/python3.10/dist-packages/uvicorn/_subprocess.py", line 76, in subprocess_started
2023-05-29 22:57:05     target(sockets=sockets)
2023-05-29 22:57:05   File "/usr/local/lib/python3.10/dist-packages/uvicorn/server.py", line 60, in run
2023-05-29 22:57:05     return asyncio.run(self.serve(sockets=sockets))
2023-05-29 22:57:05   File "/usr/lib/python3.10/asyncio/runners.py", line 44, in run
2023-05-29 22:57:05     return loop.run_until_complete(main)
2023-05-29 22:57:05   File "/usr/lib/python3.10/asyncio/base_events.py", line 633, in run_until_complete
2023-05-29 22:57:05     self.run_forever()
2023-05-29 22:57:05   File "/usr/lib/python3.10/asyncio/base_events.py", line 600, in run_forever
2023-05-29 22:57:05     self._run_once()
2023-05-29 22:57:05   File "/usr/lib/python3.10/asyncio/base_events.py", line 1896, in _run_once
2023-05-29 22:57:05     handle._run()
2023-05-29 22:57:05   File "/usr/lib/python3.10/asyncio/events.py", line 80, in _run
2023-05-29 22:57:05     self._context.run(self._callback, *self._args)
2023-05-29 22:57:05   File "/usr/local/lib/python3.10/dist-packages/uvicorn/protocols/http/httptools_impl.py", line 419, in run_asgi
2023-05-29 22:57:05     result = await app(  # type: ignore[func-returns-value]
2023-05-29 22:57:05   File "/usr/local/lib/python3.10/dist-packages/uvicorn/middleware/proxy_headers.py", line 78, in __call__
2023-05-29 22:57:05     return await self.app(scope, receive, send)
2023-05-29 22:57:05   File "/usr/local/lib/python3.10/dist-packages/fastapi/applications.py", line 271, in __call__
2023-05-29 22:57:05     await super().__call__(scope, receive, send)
2023-05-29 22:57:05   File "/usr/local/lib/python3.10/dist-packages/starlette/applications.py", line 118, in __call__
2023-05-29 22:57:05     await self.middleware_stack(scope, receive, send)
2023-05-29 22:57:05   File "/usr/local/lib/python3.10/dist-packages/starlette/middleware/errors.py", line 162, in __call__
2023-05-29 22:57:05     await self.app(scope, receive, _send)
2023-05-29 22:57:05   File "/usr/local/lib/python3.10/dist-packages/starlette/middleware/exceptions.py", line 68, in __call__
2023-05-29 22:57:05     await self.app(scope, receive, sender)
2023-05-29 22:57:05   File "/usr/local/lib/python3.10/dist-packages/fastapi/middleware/asyncexitstack.py", line 18, in __call__
2023-05-29 22:57:05     await self.app(scope, receive, send)
2023-05-29 22:57:05   File "/usr/local/lib/python3.10/dist-packages/starlette/routing.py", line 706, in __call__
2023-05-29 22:57:05     await route.handle(scope, receive, send)
2023-05-29 22:57:05   File "/usr/local/lib/python3.10/dist-packages/starlette/routing.py", line 276, in handle
2023-05-29 22:57:05     await self.app(scope, receive, send)
2023-05-29 22:57:05   File "/usr/local/lib/python3.10/dist-packages/starlette/routing.py", line 66, in app
2023-05-29 22:57:05     response = await func(request)
2023-05-29 22:57:05   File "/usr/local/lib/python3.10/dist-packages/fastapi/routing.py", line 237, in app
2023-05-29 22:57:05     raw_response = await run_endpoint_function(
2023-05-29 22:57:05   File "/usr/local/lib/python3.10/dist-packages/fastapi/routing.py", line 163, in run_endpoint_function
2023-05-29 22:57:05     return await dependant.call(**values)
2023-05-29 22:57:05   File "/./service_main.py", line 103, in read_presentation
2023-05-29 22:57:05     author = get_author(presentation.author_id)
2023-05-29 22:57:05   File "/./service_main.py", line 71, in get_author
2023-05-29 22:57:05     logging.warning(">>> Error Connecting:", errc)
2023-05-29 22:57:05 Message: '>>> Error Connecting:'
2023-05-29 22:57:05 Arguments: (ConnectionError('Service is unavailable'),)
2023-05-29 22:57:06 INFO:root:Stay Circuit breaker open
2023-05-29 22:57:06 INFO:root:Stay Circuit breaker open
2023-05-29 22:57:06 WARNING:root:Circuit "CB for Author service" is "OPEN", failures: 4
2023-05-29 22:57:06 WARNING:root:
2023-05-29 22:57:06 INFO:root:Stay Circuit breaker open
2023-05-29 22:57:07 WARNING:root:Circuit "CB for Author service" is "OPEN", failures: 4
2023-05-29 22:57:07 WARNING:root:
2023-05-29 22:57:07 INFO:root:Stay Circuit breaker open
2023-05-29 22:57:08 INFO:root:Stay Circuit breaker open
2023-05-29 22:57:08 WARNING:root:Circuit "CB for Author service" is "OPEN", failures: 4
2023-05-29 22:57:08 WARNING:root:
2023-05-29 22:57:09 INFO:root:Stay Circuit breaker open
2023-05-29 22:57:09 WARNING:root:Circuit "CB for Author service" is "OPEN", failures: 4
2023-05-29 22:57:09 WARNING:root:
2023-05-29 22:57:10 INFO:root:Stay Circuit breaker open
2023-05-29 22:57:10 WARNING:root:Circuit "CB for Author service" is "OPEN", failures: 4
2023-05-29 22:57:10 WARNING:root:
2023-05-29 22:57:11 WARNING:root:Circuit "CB for Author service" is "OPEN", failures: 4
2023-05-29 22:57:11 WARNING:root:
2023-05-29 22:57:12 WARNING:root:Circuit "CB for Author service" is "OPEN", failures: 4
2023-05-29 22:57:12 WARNING:root:
2023-05-29 22:57:13 WARNING:root:Circuit "CB for Author service" is "OPEN", failures: 4
2023-05-29 22:57:13 WARNING:root:
2023-05-29 22:57:14 WARNING:root:Circuit "CB for Author service" is "OPEN", failures: 4
2023-05-29 22:57:14 WARNING:root:
2023-05-29 22:57:15 WARNING:root:Circuit "CB for Author service" is "OPEN", failures: 4
2023-05-29 22:57:15 WARNING:root:
2023-05-29 22:57:16 WARNING:root:Circuit "CB for Author service" is "OPEN", failures: 4
2023-05-29 22:57:16 WARNING:root:
2023-05-29 22:57:17 INFO:root:Try half_open Circuit breaker
2023-05-29 22:57:17 WARNING:root:Request failed
2023-05-29 22:57:17 --- Logging error ---
2023-05-29 22:57:17 Traceback (most recent call last):
2023-05-29 22:57:17   File "/usr/local/lib/python3.10/dist-packages/urllib3/connection.py", line 174, in _new_conn
2023-05-29 22:57:17     conn = connection.create_connection(
2023-05-29 22:57:17   File "/usr/local/lib/python3.10/dist-packages/urllib3/util/connection.py", line 95, in create_connection
2023-05-29 22:57:17     raise err
2023-05-29 22:57:17   File "/usr/local/lib/python3.10/dist-packages/urllib3/util/connection.py", line 85, in create_connection
2023-05-29 22:57:17     sock.connect(sa)
2023-05-29 22:57:17 ConnectionRefusedError: [Errno 111] Connection refused
2023-05-29 22:57:17 
2023-05-29 22:57:17 During handling of the above exception, another exception occurred:
2023-05-29 22:57:17 
2023-05-29 22:57:17 Traceback (most recent call last):
2023-05-29 22:57:17   File "/usr/local/lib/python3.10/dist-packages/urllib3/connectionpool.py", line 703, in urlopen
2023-05-29 22:57:17     httplib_response = self._make_request(
2023-05-29 22:57:17   File "/usr/local/lib/python3.10/dist-packages/urllib3/connectionpool.py", line 398, in _make_request
2023-05-29 22:57:17     conn.request(method, url, **httplib_request_kw)
2023-05-29 22:57:17   File "/usr/local/lib/python3.10/dist-packages/urllib3/connection.py", line 239, in request
2023-05-29 22:57:17     super(HTTPConnection, self).request(method, url, body=body, headers=headers)
2023-05-29 22:57:17   File "/usr/lib/python3.10/http/client.py", line 1282, in request
2023-05-29 22:57:17     self._send_request(method, url, body, headers, encode_chunked)
2023-05-29 22:57:17   File "/usr/lib/python3.10/http/client.py", line 1328, in _send_request
2023-05-29 22:57:17     self.endheaders(body, encode_chunked=encode_chunked)
2023-05-29 22:57:17   File "/usr/lib/python3.10/http/client.py", line 1277, in endheaders
2023-05-29 22:57:17     self._send_output(message_body, encode_chunked=encode_chunked)
2023-05-29 22:57:17   File "/usr/lib/python3.10/http/client.py", line 1037, in _send_output
2023-05-29 22:57:17     self.send(msg)
2023-05-29 22:57:17   File "/usr/lib/python3.10/http/client.py", line 975, in send
2023-05-29 22:57:17     self.connect()
2023-05-29 22:57:17   File "/usr/local/lib/python3.10/dist-packages/urllib3/connection.py", line 205, in connect
2023-05-29 22:57:17     conn = self._new_conn()
2023-05-29 22:57:17   File "/usr/local/lib/python3.10/dist-packages/urllib3/connection.py", line 186, in _new_conn
2023-05-29 22:57:17     raise NewConnectionError(
2023-05-29 22:57:17 urllib3.exceptions.NewConnectionError: <urllib3.connection.HTTPConnection object at 0x7fc9482f8730>: Failed to establish a new connection: [Errno 111] Connection refused
2023-05-29 22:57:17 
2023-05-29 22:57:17 During handling of the above exception, another exception occurred:
2023-05-29 22:57:17 
2023-05-29 22:57:17 Traceback (most recent call last):
2023-05-29 22:57:17   File "/usr/local/lib/python3.10/dist-packages/requests/adapters.py", line 489, in send
2023-05-29 22:57:17     resp = conn.urlopen(
2023-05-29 22:57:17   File "/usr/local/lib/python3.10/dist-packages/urllib3/connectionpool.py", line 787, in urlopen
2023-05-29 22:57:17     retries = retries.increment(
2023-05-29 22:57:17   File "/usr/local/lib/python3.10/dist-packages/urllib3/util/retry.py", line 592, in increment
2023-05-29 22:57:17     raise MaxRetryError(_pool, url, error or ResponseError(cause))
2023-05-29 22:57:17 urllib3.exceptions.MaxRetryError: HTTPConnectionPool(host='service_author', port=8081): Max retries exceeded with url: /authors/1 (Caused by NewConnectionError('<urllib3.connection.HTTPConnection object at 0x7fc9482f8730>: Failed to establish a new connection: [Errno 111] Connection refused'))
2023-05-29 22:57:17 
2023-05-29 22:57:17 During handling of the above exception, another exception occurred:
2023-05-29 22:57:17 
2023-05-29 22:57:17 Traceback (most recent call last):
2023-05-29 22:57:17   File "/./custom_cb.py", line 29, in execute
2023-05-29 22:57:17     response = requests.get(url, timeout=3)
2023-05-29 22:57:17   File "/usr/local/lib/python3.10/dist-packages/requests/api.py", line 73, in get
2023-05-29 22:57:17     return request("get", url, params=params, **kwargs)
2023-05-29 22:57:17   File "/usr/local/lib/python3.10/dist-packages/requests/api.py", line 59, in request
2023-05-29 22:57:17     return session.request(method=method, url=url, **kwargs)
2023-05-29 22:57:17   File "/usr/local/lib/python3.10/dist-packages/requests/sessions.py", line 587, in request
2023-05-29 22:57:17     resp = self.send(prep, **send_kwargs)
2023-05-29 22:57:17   File "/usr/local/lib/python3.10/dist-packages/requests/sessions.py", line 701, in send
2023-05-29 22:57:17     r = adapter.send(request, **kwargs)
2023-05-29 22:57:17   File "/usr/local/lib/python3.10/dist-packages/requests/adapters.py", line 565, in send
2023-05-29 22:57:17     raise ConnectionError(e, request=request)
2023-05-29 22:57:17 requests.exceptions.ConnectionError: HTTPConnectionPool(host='service_author', port=8081): Max retries exceeded with url: /authors/1 (Caused by NewConnectionError('<urllib3.connection.HTTPConnection object at 0x7fc9482f8730>: Failed to establish a new connection: [Errno 111] Connection refused'))
2023-05-29 22:57:17 
2023-05-29 22:57:17 During handling of the above exception, another exception occurred:
2023-05-29 22:57:17 
2023-05-29 22:57:17 Traceback (most recent call last):
2023-05-29 22:57:17   File "/./service_main.py", line 69, in get_author
2023-05-29 22:57:17     response_author = cb.execute("http://" + service_author + "/authors/" + str(id), get_author_fallback())
2023-05-29 22:57:17   File "/./custom_cb.py", line 41, in execute
2023-05-29 22:57:17     raise ConnectionError('Service is unavailable')
2023-05-29 22:57:17 ConnectionError: Service is unavailable
2023-05-29 22:57:17 
2023-05-29 22:57:17 During handling of the above exception, another exception occurred:
2023-05-29 22:57:17 
2023-05-29 22:57:17 Traceback (most recent call last):
2023-05-29 22:57:17   File "/usr/lib/python3.10/logging/__init__.py", line 1100, in emit
2023-05-29 22:57:17     msg = self.format(record)
2023-05-29 22:57:17   File "/usr/lib/python3.10/logging/__init__.py", line 943, in format
2023-05-29 22:57:17     return fmt.format(record)
2023-05-29 22:57:17   File "/usr/lib/python3.10/logging/__init__.py", line 678, in format
2023-05-29 22:57:17     record.message = record.getMessage()
2023-05-29 22:57:17   File "/usr/lib/python3.10/logging/__init__.py", line 368, in getMessage
2023-05-29 22:57:17     msg = msg % self.args
2023-05-29 22:57:17 TypeError: not all arguments converted during string formatting
2023-05-29 22:57:17 Call stack:
2023-05-29 22:57:17   File "<string>", line 1, in <module>
2023-05-29 22:57:17   File "/usr/lib/python3.10/multiprocessing/spawn.py", line 116, in spawn_main
2023-05-29 22:57:17     exitcode = _main(fd, parent_sentinel)
2023-05-29 22:57:17   File "/usr/lib/python3.10/multiprocessing/spawn.py", line 129, in _main
2023-05-29 22:57:17     return self._bootstrap(parent_sentinel)
2023-05-29 22:57:17   File "/usr/lib/python3.10/multiprocessing/process.py", line 314, in _bootstrap
2023-05-29 22:57:17 INFO:     172.20.0.1:48116 - "GET /presentationsAndAuthor/First%20Presentation HTTP/1.1" 500 Internal Server Error
2023-05-29 22:57:17     self.run()
2023-05-29 22:57:17   File "/usr/lib/python3.10/multiprocessing/process.py", line 108, in run
2023-05-29 22:57:17     self._target(*self._args, **self._kwargs)
2023-05-29 22:57:17   File "/usr/local/lib/python3.10/dist-packages/uvicorn/_subprocess.py", line 76, in subprocess_started
2023-05-29 22:57:17     target(sockets=sockets)
2023-05-29 22:57:17   File "/usr/local/lib/python3.10/dist-packages/uvicorn/server.py", line 60, in run
2023-05-29 22:57:17     return asyncio.run(self.serve(sockets=sockets))
2023-05-29 22:57:17   File "/usr/lib/python3.10/asyncio/runners.py", line 44, in run
2023-05-29 22:57:17     return loop.run_until_complete(main)
2023-05-29 22:57:17   File "/usr/lib/python3.10/asyncio/base_events.py", line 633, in run_until_complete
2023-05-29 22:57:17     self.run_forever()
2023-05-29 22:57:17   File "/usr/lib/python3.10/asyncio/base_events.py", line 600, in run_forever
2023-05-29 22:57:17     self._run_once()
2023-05-29 22:57:17   File "/usr/lib/python3.10/asyncio/base_events.py", line 1896, in _run_once
2023-05-29 22:57:17     handle._run()
2023-05-29 22:57:17   File "/usr/lib/python3.10/asyncio/events.py", line 80, in _run
2023-05-29 22:57:17     self._context.run(self._callback, *self._args)
2023-05-29 22:57:17   File "/usr/local/lib/python3.10/dist-packages/uvicorn/protocols/http/httptools_impl.py", line 419, in run_asgi
2023-05-29 22:57:17     result = await app(  # type: ignore[func-returns-value]
2023-05-29 22:57:17   File "/usr/local/lib/python3.10/dist-packages/uvicorn/middleware/proxy_headers.py", line 78, in __call__
2023-05-29 22:57:17     return await self.app(scope, receive, send)
2023-05-29 22:57:17   File "/usr/local/lib/python3.10/dist-packages/fastapi/applications.py", line 271, in __call__
2023-05-29 22:57:17     await super().__call__(scope, receive, send)
2023-05-29 22:57:17   File "/usr/local/lib/python3.10/dist-packages/starlette/applications.py", line 118, in __call__
2023-05-29 22:57:17     await self.middleware_stack(scope, receive, send)
2023-05-29 22:57:17   File "/usr/local/lib/python3.10/dist-packages/starlette/middleware/errors.py", line 162, in __call__
2023-05-29 22:57:17     await self.app(scope, receive, _send)
2023-05-29 22:57:17   File "/usr/local/lib/python3.10/dist-packages/starlette/middleware/exceptions.py", line 68, in __call__
2023-05-29 22:57:17     await self.app(scope, receive, sender)
2023-05-29 22:57:17   File "/usr/local/lib/python3.10/dist-packages/fastapi/middleware/asyncexitstack.py", line 18, in __call__
2023-05-29 22:57:17     await self.app(scope, receive, send)
2023-05-29 22:57:17   File "/usr/local/lib/python3.10/dist-packages/starlette/routing.py", line 706, in __call__
2023-05-29 22:57:17     await route.handle(scope, receive, send)
2023-05-29 22:57:17   File "/usr/local/lib/python3.10/dist-packages/starlette/routing.py", line 276, in handle
2023-05-29 22:57:17     await self.app(scope, receive, send)
2023-05-29 22:57:17   File "/usr/local/lib/python3.10/dist-packages/starlette/routing.py", line 66, in app
2023-05-29 22:57:17     response = await func(request)
2023-05-29 22:57:17   File "/usr/local/lib/python3.10/dist-packages/fastapi/routing.py", line 237, in app
2023-05-29 22:57:17     raw_response = await run_endpoint_function(
2023-05-29 22:57:17   File "/usr/local/lib/python3.10/dist-packages/fastapi/routing.py", line 163, in run_endpoint_function
2023-05-29 22:57:17     return await dependant.call(**values)
2023-05-29 22:57:17   File "/./service_main.py", line 103, in read_presentation
2023-05-29 22:57:17     author = get_author(presentation.author_id)
2023-05-29 22:57:17   File "/./service_main.py", line 71, in get_author
2023-05-29 22:57:17     logging.warning(">>> Error Connecting:", errc)
2023-05-29 22:57:17 Message: '>>> Error Connecting:'
2023-05-29 22:57:17 Arguments: (ConnectionError('Service is unavailable'),)
2023-05-29 22:57:17 WARNING:root:Circuit "CB for Author service" is "OPEN", failures: 5
2023-05-29 22:57:17 WARNING:root:
2023-05-29 22:57:18 WARNING:root:Circuit "CB for Author service" is "OPEN", failures: 5
2023-05-29 22:57:18 WARNING:root:
2023-05-29 22:57:19 INFO:root:Stay Circuit breaker open
2023-05-29 22:57:19 temporary unavailable
2023-05-29 22:57:19 INFO:     172.20.0.1:48122 - "GET /presentationsAndAuthor/First%20Presentation HTTP/1.1" 200 OK
2023-05-29 22:57:19 WARNING:root:Circuit "CB for Author service" is "OPEN", failures: 5
2023-05-29 22:57:19 WARNING:root:
2023-05-29 22:57:20 WARNING:root:Circuit "CB for Author service" is "OPEN", failures: 5
2023-05-29 22:57:20 WARNING:root:
2023-05-29 22:57:21 INFO:root:Stay Circuit breaker open
2023-05-29 22:57:21 temporary unavailable
2023-05-29 22:57:21 INFO:     172.20.0.1:48126 - "GET /presentationsAndAuthor/First%20Presentation HTTP/1.1" 200 OK
2023-05-29 22:57:21 WARNING:root:Circuit "CB for Author service" is "OPEN", failures: 5
2023-05-29 22:57:21 WARNING:root:
2023-05-29 22:57:22 WARNING:root:Circuit "CB for Author service" is "OPEN", failures: 5
2023-05-29 22:57:22 WARNING:root:
2023-05-29 22:57:23 temporary unavailable
2023-05-29 22:57:23 INFO:     172.20.0.1:48130 - "GET /presentationsAndAuthor/First%20Presentation HTTP/1.1" 200 OK
2023-05-29 22:57:23 INFO:root:Stay Circuit breaker open
2023-05-29 22:57:23 INFO:root:Stay Circuit breaker open
2023-05-29 22:57:23 temporary unavailable
2023-05-29 22:57:23 INFO:     172.20.0.1:48134 - "GET /presentationsAndAuthor/First%20Presentation HTTP/1.1" 200 OK
2023-05-29 22:57:23 WARNING:root:Circuit "CB for Author service" is "OPEN", failures: 5
2023-05-29 22:57:23 WARNING:root:
2023-05-29 22:57:24 temporary unavailable
2023-05-29 22:57:24 INFO:     172.20.0.1:48138 - "GET /presentationsAndAuthor/First%20Presentation HTTP/1.1" 200 OK
2023-05-29 22:57:24 INFO:root:Stay Circuit breaker open
2023-05-29 22:57:24 WARNING:root:Circuit "CB for Author service" is "OPEN", failures: 5
2023-05-29 22:57:24 WARNING:root:
2023-05-29 22:57:25 INFO:root:Stay Circuit breaker open
2023-05-29 22:57:25 temporary unavailable
2023-05-29 22:57:25 INFO:     172.20.0.1:48142 - "GET /presentationsAndAuthor/First%20Presentation HTTP/1.1" 200 OK
2023-05-29 22:57:25 WARNING:root:Circuit "CB for Author service" is "OPEN", failures: 5
2023-05-29 22:57:25 WARNING:root:
2023-05-29 22:57:26 INFO:root:Stay Circuit breaker open
2023-05-29 22:57:26 temporary unavailable
2023-05-29 22:57:26 INFO:     172.20.0.1:48146 - "GET /presentationsAndAuthor/First%20Presentation HTTP/1.1" 200 OK
2023-05-29 22:57:26 WARNING:root:Circuit "CB for Author service" is "OPEN", failures: 5
2023-05-29 22:57:26 WARNING:root:
2023-05-29 22:57:27 INFO:root:Try half_open Circuit breaker
2023-05-29 22:57:27 INFO:root:Request successful
2023-05-29 22:57:27 Moore
2023-05-29 22:57:27 INFO:     172.20.0.1:48150 - "GET /presentationsAndAuthor/First%20Presentation HTTP/1.1" 200 OK
2023-05-29 22:57:27 WARNING:root:Circuit "CB for Author service" is "CLOSED", failures: 0
2023-05-29 22:57:27 WARNING:root:
2023-05-29 22:57:29 WARNING:root:Circuit "CB for Author service" is "CLOSED", failures: 0
2023-05-29 22:57:29 WARNING:root:
2023-05-29 22:57:30 WARNING:root:Circuit "CB for Author service" is "CLOSED", failures: 0
2023-05-29 22:57:30 WARNING:root:
2023-05-29 22:57:31 WARNING:root:Circuit "CB for Author service" is "CLOSED", failures: 0
2023-05-29 22:57:31 WARNING:root:
2023-05-29 22:57:32 WARNING:root:Circuit "CB for Author service" is "CLOSED", failures: 0
2023-05-29 22:57:32 WARNING:root:
2023-05-29 22:57:33 WARNING:root:Circuit "CB for Author service" is "CLOSED", failures: 0
2023-05-29 22:57:33 WARNING:root:
2023-05-29 22:57:34 WARNING:root:Circuit "CB for Author service" is "CLOSED", failures: 0
2023-05-29 22:57:34 WARNING:root:
2023-05-29 22:57:35 WARNING:root:Circuit "CB for Author service" is "CLOSED", failures: 0
2023-05-29 22:57:35 WARNING:root:
2023-05-29 22:57:36 WARNING:root:Circuit "CB for Author service" is "CLOSED", failures: 0
2023-05-29 22:57:36 WARNING:root:
2023-05-29 22:57:37 WARNING:root:Circuit "CB for Author service" is "CLOSED", failures: 0
2023-05-29 22:57:37 WARNING:root:
2023-05-29 22:57:38 WARNING:root:Circuit "CB for Author service" is "CLOSED", failures: 0
2023-05-29 22:57:38 WARNING:root:
2023-05-29 22:57:39 WARNING:root:Circuit "CB for Author service" is "CLOSED", failures: 0
2023-05-29 22:57:39 WARNING:root:
2023-05-29 22:57:40 WARNING:root:Circuit "CB for Author service" is "CLOSED", failures: 0
2023-05-29 22:57:40 WARNING:root:
2023-05-29 22:57:41 WARNING:root:Circuit "CB for Author service" is "CLOSED", failures: 0
2023-05-29 22:57:41 WARNING:root:
2023-05-29 22:57:42 WARNING:root:Circuit "CB for Author service" is "CLOSED", failures: 0
2023-05-29 22:57:42 WARNING:root:
2023-05-29 22:57:43 WARNING:root:Circuit "CB for Author service" is "CLOSED", failures: 0
2023-05-29 22:57:43 WARNING:root:
